Workbook

Sheet Active Jobs Sheet
A1: Office | B1: Project # | C1: Project Name | D1: PM | E1: Contract to Date | F1: Billed to Date | G1: Remaining Billings | H1: Mar-26 | I1: Apr-26 | J1: May-26 | K1: Jun-26 | L1: Jul-26 | M1: Aug-26 | N1: Sep-26 | O1: Oct-26 | P1: Nov-26 | Q1: Dec-26 | R1: Zero Balance | S1: Notes
A2: CLE | B2: 23-22 | C2: GSA Celebrezze | D2: A.E. | E2: =VLOOKUP($B2,'Foundation Inport'!$A$2:$H$52,3,FALSE) -> 309888.75 | F2: =IF(VLOOKUP($B2,'Foundation Inport'!$A$2:$H$592,4,FALSE)>0,VLOOKUP($B2,'Foundation Inport'!$A$2:$H$592,4,FALSE),0) -> 266144.9 | G2: =E2-F2 -> 43743.85 | H2: 14932.5 | I2: 28811.35 | R2: =G2-SUM(H2:Q2) -> 0
A3: CBUS | B3: 23-46 | C3: Galaxy I | D3: R.S. | E3: =VLOOKUP($B3,'Foundation Inport'!$A$2:$H$10,3,FALSE) -> 637845.28 | F3: =IF(VLOOKUP($B3,'Foundation Inport'!$A$2:$H$592,4,FALSE)>0,VLOOKUP($B3,'Foundation Inport'!$A$2:$H$592,4,FALSE),0) -> 637845.28 | G3: =E3-F3 -> 0 | R3: =G3-SUM(H3:Q3) -> 0
A4: CBUS | B4: 24-13 | C4: TWHS Natatorium | D4: R.S. | E4: =VLOOKUP($B4,'Foundation Inport'!$A$2:$H$10,3,FALSE) -> 416108.63 | F4: =IF(VLOOKUP($B4,'Foundation Inport'!$A$2:$H$592,4,FALSE)>0,VLOOKUP($B4,'Foundation Inport'!$A$2:$H$592,4,FALSE),0) -> 416108.63 | G4: =E4-F4 -> 0 | R4: =G4-SUM(H4:Q4) -> 0
A5: CBUS | B5: 24-22 | C5: Daimler Truck | D5: R.S. | E5: =VLOOKUP($B5,'Foundation Inport'!$A$2:$H$10,3,FALSE) -> 655214.83 | F5: =IF(VLOOKUP($B5,'Foundation Inport'!$A$2:$H$592,4,FALSE)>0,VLOOKUP($B5,'Foundation Inport'!$A$2:$H$592,4,FALSE),0) -> 499895.2 | G5: =E5-F5 -> 155319.63 | H5: 143444.88 | I5: 11874.75 | R5: =G5-SUM(H5:Q5) -> 0
A6: CLE | B6: 24-26 | C6: St Michael of Arch | D6: D.S. | E6: =VLOOKUP($B6,'Foundation Inport'!$A$2:$H$10,3,FALSE) -> 81936.5 | F6: =IF(VLOOKUP($B6,'Foundation Inport'!$A$2:$H$592,4,FALSE)>0,VLOOKUP($B6,'Foundation Inport'!$A$2:$H$592,4,FALSE),0) -> 81936.5 | G6: =E6-F6 -> 0 | R6: =G6-SUM(H6:Q6) -> 0
A7: CBUS | B7: 24-34 | C7: Pickerington Centeral JHS | D7: A.E. | E7: =VLOOKUP($B7,'Foundation Inport'!$A$2:$H$10,3,FALSE) -> 1438021.3 | F7: =IF(VLOOKUP($B7,'Foundation Inport'!$A$2:$H$592,4,FALSE)>0,VLOOKUP($B7,'Foundation Inport'!$A$2:$H$592,4,FALSE),0) -> 1416391.3 | G7: =E7-F7 -> 21630 | I7: 21630 | R7: =G7-SUM(H7:Q7) -> 0
A8: CBUS | B8: 24-45 | C8: Columbus Fire Station #36 | D8: R.S. | E8: =VLOOKUP($B8,'Foundation Inport'!$A$2:$H$10,3,FALSE) -> 196562 | F8: =IF(VLOOKUP($B8,'Foundation Inport'!$A$2:$H$592,4,FALSE)>0,VLOOKUP($B8,'Foundation Inport'!$A$2:$H$592,4,FALSE),0) -> 155550 | G8: =E8-F8 -> 41012 | H8: 23150 | I8: 17862 | R8: =G8-SUM(H8:Q8) -> 0
A9: CLE | B9: 24-50 | C9: North Olmsted PK-5 | D9: C.G. | E9: =VLOOKUP($B9,'Foundation Inport'!$A$2:$H$10,3,FALSE) -> 1949570.4 | F9: =IF(VLOOKUP($B9,'Foundation Inport'!$A$2:$H$592,4,FALSE)>0,VLOOKUP($B9,'Foundation Inport'!$A$2:$H$592,4,FALSE),0) -> 1499798.9 | G9: =E9-F9 -> 449771.57 | H9: 79387.54 | I9: 60000 | J9: 100000 | K9: 210384.03 | R9: =G9-SUM(H9:Q9) -> 0
A10: CLE | B10: 24-55 | C10: Amherst Transportation Bldg | D10: C.G. | E10: =VLOOKUP($B10,'Foundation Inport'!$A$2:$H$13,3,FALSE) -> 75507.6 | F10: =IF(VLOOKUP($B10,'Foundation Inport'!$A$2:$H$592,4,FALSE)>0,VLOOKUP($B10,'Foundation Inport'!$A$2:$H$592,4,FALSE),0) -> 46635.09 | G10: =E10-F10 -> 28872.51 | I10: 28872.51 | R10: =G10-SUM(H10:Q10) -> 0
A11: CLE | B11: 24-56 | C11: Lake County Executive Airport | D11: C.G. | E11: =VLOOKUP($B11,'Foundation Inport'!$A$2:$H$13,3,FALSE) -> 323945.76 | F11: =IF(VLOOKUP($B11,'Foundation Inport'!$A$2:$H$592,4,FALSE)>0,VLOOKUP($B11,'Foundation Inport'!$A$2:$H$592,4,FALSE),0) -> 262683.83 | G11: =E11-F11 -> 61261.93 | H11: 55289.93 | I11: 5972 | R11: =G11-SUM(H11:Q11) -> 0
A12: CBUS | B12: 25-01 | C12: Westerville City Hall | D12: R.S. | E12: =VLOOKUP($B12,'Foundation Inport'!$A$2:$H$13,3,FALSE) -> 1010713.8 | F12: =IF(VLOOKUP($B12,'Foundation Inport'!$A$2:$H$592,4,FALSE)>0,VLOOKUP($B12,'Foundation Inport'!$A$2:$H$592,4,FALSE),0) -> 765217.42 | G12: =E12-F12 -> 245496.35 | I12: 177759.35 | J12: 30000 | K12: 37737 | R12: =G12-SUM(H12:Q12) -> 0
A13: CBUS | B13: 25-21 | C13: Everhome Suites (Furnish Windows) | D13: R.S. | E13: =VLOOKUP($B13,'Foundation Inport'!$A$2:$H$22,3,FALSE) -> 113552 | F13: =IF(VLOOKUP($B13,'Foundation Inport'!$A$2:$H$592,4,FALSE)>0,VLOOKUP($B13,'Foundation Inport'!$A$2:$H$592,4,FALSE),0) -> 37472 | G13: =E13-F13 -> 76080 | L13: 76080 | R13: =G13-SUM(H13:Q13) -> 0
A14: CBUS | B14: 25-22 | C14: Parsons Ave Water Plant | D14: R.S. | E14: =VLOOKUP($B14,'Foundation Inport'!$A$2:$H$22,3,FALSE) -> 46665 | F14: =IF(VLOOKUP($B14,'Foundation Inport'!$A$2:$H$592,4,FALSE)>0,VLOOKUP($B14,'Foundation Inport'!$A$2:$H$592,4,FALSE),0) -> 3500 | G14: =E14-F14 -> 43165 | H14: 38279 | I14: 4886 | R14: =G14-SUM(H14:Q14) -> 0
A15: CBUS | B15: 25-28 | C15: Commons at Grant | D15: C.G. | E15: =VLOOKUP($B15,'Foundation Inport'!$A$2:$H$50,3,FALSE) -> 663912.15 | F15: =IF(VLOOKUP($B15,'Foundation Inport'!$A$2:$H$592,4,FALSE)>0,VLOOKUP($B15,'Foundation Inport'!$A$2:$H$592,4,FALSE),0) -> 391727.69 | G15: =E15-F15 -> 272184.46 | H15: 56499.9 | I15: 98062.54 | J15: 117622.02 | R15: =G15-SUM(H15:Q15) -> 0
A16: CBUS | B16: 25-31 | C16: Riffe 25th Floor | D16: TBD | E16: =VLOOKUP($B16,'Foundation Inport'!$A$2:$H$42,3,FALSE) -> 4950 | F16: =IF(VLOOKUP($B16,'Foundation Inport'!$A$2:$H$592,4,FALSE)>0,VLOOKUP($B16,'Foundation Inport'!$A$2:$H$592,4,FALSE),0) -> 4950 | G16: =E16-F16 -> 0 | R16: =G16-SUM(H16:Q16) -> 0
A17: CBUS | B17: 25-32 | C17: Channing Street Redevelopment | D17: C.G. | E17: =VLOOKUP($B17,'Foundation Inport'!$A$2:$H$42,3,FALSE) -> 61379 | F17: =IF(VLOOKUP($B17,'Foundation Inport'!$A$2:$H$592,4,FALSE)>0,VLOOKUP($B17,'Foundation Inport'!$A$2:$H$592,4,FALSE),0) -> 35507.68 | G17: =E17-F17 -> 25871.32 | J17: 25871.32 | R17: =G17-SUM(H17:Q17) -> 0
A18: CBUS | B18: 25-34 | C18: Mad River | D18: C.G. | E18: =VLOOKUP($B18,'Foundation Inport'!$A$2:$H$50,3,FALSE) -> 82389 | F18: =IF(VLOOKUP($B18,'Foundation Inport'!$A$2:$H$592,4,FALSE)>0,VLOOKUP($B18,'Foundation Inport'!$A$2:$H$592,4,FALSE),0) -> 49639 | G18: =E18-F18 -> 32750 | H18: 32750 | R18: =G18-SUM(H18:Q18) -> 0
A19: CBUS | B19: 25-35 | C19: North Crest | D19: R.S. | E19: =VLOOKUP($B19,'Foundation Inport'!$A$2:$H$50,3,FALSE) -> 44652 | F19: =IF(VLOOKUP($B19,'Foundation Inport'!$A$2:$H$592,4,FALSE)>0,VLOOKUP($B19,'Foundation Inport'!$A$2:$H$592,4,FALSE),0) -> 37987.75 | G19: =E19-F19 -> 6664.25 | H19: 5054.75 | I19: 1609.5 | R19: =G19-SUM(H19:Q19) -> 0
A20: CBUS | B20: 25-38 | C20: ODOT Auglaize County | D20: C.G. | E20: =VLOOKUP($B20,'Foundation Inport'!$A$2:$H$42,3,FALSE) -> 189316 | F20: =IF(VLOOKUP($B20,'Foundation Inport'!$A$2:$H$592,4,FALSE)>0,VLOOKUP($B20,'Foundation Inport'!$A$2:$H$592,4,FALSE),0) -> 161095 | G20: =E20-F20 -> 28221 | H20: 23829 | I20: 4392 | R20: =G20-SUM(H20:Q20) -> 0
A21: CLE | B21: 25-43 | C21: Halloran Skating Park | D21: R.S. | E21: =VLOOKUP($B21,'Foundation Inport'!$A$2:$H$52,3,FALSE) -> 171150 | F21: =IF(VLOOKUP($B21,'Foundation Inport'!$A$2:$H$592,4,FALSE)>0,VLOOKUP($B21,'Foundation Inport'!$A$2:$H$592,4,FALSE),0) -> 72943 | G21: =E21-F21 -> 98207 | I21: 89000 | J21: 9207 | R21: =G21-SUM(H21:Q21) -> 0
A22: CLE | B22: 25-46 | C22: Foster Senior Lofts | D22: D.S. | E22: =VLOOKUP($B22,'Foundation Inport'!$A$2:$H$52,3,FALSE) -> 25250 | F22: =IF(VLOOKUP($B22,'Foundation Inport'!$A$2:$H$592,4,FALSE)>0,VLOOKUP($B22,'Foundation Inport'!$A$2:$H$592,4,FALSE),0) -> 5000 | G22: =E22-F22 -> 20250 | H22: 19800 | I22: 450 | R22: =G22-SUM(H22:Q22) -> 0
A23: CLE | B23: 25-47 | C23: ODOT Lake County | D23: C.G. | E23: =VLOOKUP($B23,'Foundation Inport'!$A$2:$H$52,3,FALSE) -> 159220 | F23: =IF(VLOOKUP($B23,'Foundation Inport'!$A$2:$H$592,4,FALSE)>0,VLOOKUP($B23,'Foundation Inport'!$A$2:$H$592,4,FALSE),0) -> 6338 | G23: =E23-F23 -> 152882 | I23: 77882 | J23: 75000 | R23: =G23-SUM(H23:Q23) -> 0
A24: CBUS | B24: 25-48 | C24: ODOT Delaware County | D24: C.G. | E24: =VLOOKUP($B24,'Foundation Inport'!$A$2:$H$52,3,FALSE) -> 159220 | F24: =IF(VLOOKUP($B24,'Foundation Inport'!$A$2:$H$592,4,FALSE)>0,VLOOKUP($B24,'Foundation Inport'!$A$2:$H$592,4,FALSE),0) -> 6338 | G24: =E24-F24 -> 152882 | I24: 77882 | J24: 75000 | R24: =G24-SUM(H24:Q24) -> 0
A25: CLE | B25: 25-49 | C25: Furnace Street Apartments | D25: D.S. | E25: =VLOOKUP($B25,'Foundation Inport'!$A$2:$H$52,3,FALSE) -> 43540 | F25: =IF(VLOOKUP($B25,'Foundation Inport'!$A$2:$H$592,4,FALSE)>0,VLOOKUP($B25,'Foundation Inport'!$A$2:$H$592,4,FALSE),0) -> 5000 | G25: =E25-F25 -> 38540 | H25: 33000 | I25: 5540 | R25: =G25-SUM(H25:Q25) -> 0
A26: CBUS | B26: 25-52 | C26: Jefferson Fire Station | D26: C.G. | E26: =VLOOKUP($B26,'Foundation Inport'!$A$2:$H$52,3,FALSE) -> 59390 | F26: =IF(VLOOKUP($B26,'Foundation Inport'!$A$2:$H$592,4,FALSE)>0,VLOOKUP($B26,'Foundation Inport'!$A$2:$H$592,4,FALSE),0) -> 4500 | G26: =E26-F26 -> 54890 | J26: 54890 | R26: =G26-SUM(H26:Q26) -> 0
A27: CLE | B27: 25-57 | C27: North Fork | D27: R.S. | E27: =VLOOKUP($B27,'Foundation Inport'!$A$2:$H$52,3,FALSE) -> 6418 | F27: =IF(VLOOKUP($B27,'Foundation Inport'!$A$2:$H$592,4,FALSE)>0,VLOOKUP($B27,'Foundation Inport'!$A$2:$H$592,4,FALSE),0) -> 0 | G27: =E27-F27 -> 6418 | I27: 6418 | R27: =G27-SUM(H27:Q27) -> 0
A28: CBUS | B28: 25-58 | C28: New Seasons Dayton | D28: R.S. | E28: =VLOOKUP($B28,'Foundation Inport'!$A$2:$H$52,3,FALSE) -> 6650 | F28: =IF(VLOOKUP($B28,'Foundation Inport'!$A$2:$H$592,4,FALSE)>0,VLOOKUP($B28,'Foundation Inport'!$A$2:$H$592,4,FALSE),0) -> 6650 | G28: =E28-F28 -> 0 | R28: =G28-SUM(H28:Q28) -> 0
A29: CLE | B29: 25-59 | C29: Hernandez Office | D29: R.S. | E29: =VLOOKUP($B29,'Foundation Inport'!$A$2:$H$52,3,FALSE) -> 9866.5 | F29: =IF(VLOOKUP($B29,'Foundation Inport'!$A$2:$H$592,4,FALSE)>0,VLOOKUP($B29,'Foundation Inport'!$A$2:$H$592,4,FALSE),0) -> 9866.5 | G29: =E29-F29 -> 0 | R29: =G29-SUM(H29:Q29) -> 0
A30: CLE | B30: 25-60 | C30: 12200 Alameda | D30: C.G. | E30: =VLOOKUP($B30,'Foundation Inport'!$A$2:$H$52,3,FALSE) -> 95668 | F30: =IF(VLOOKUP($B30,'Foundation Inport'!$A$2:$H$592,4,FALSE)>0,VLOOKUP($B30,'Foundation Inport'!$A$2:$H$592,4,FALSE),0) -> 47834 | G30: =E30-F30 -> 47834 | H30: 38267.2 | I30: 9566.8 | R30: =G30-SUM(H30:Q30) -> 0
A31: CLE | B31: 25-61 | C31: Nobility Court | D31: C.G. | E31: =VLOOKUP($B31,'Foundation Inport'!$A$2:$H$67,3,FALSE) -> 85225 | F31: =IF(VLOOKUP($B31,'Foundation Inport'!$A$2:$H$592,4,FALSE)>0,VLOOKUP($B31,'Foundation Inport'!$A$2:$H$592,4,FALSE),0) -> 0 | G31: =E31-F31 -> 85225 | H31: 5000 | I31: 40225 | J31: 40000 | R31: =G31-SUM(H31:Q31) -> 0
A32: CLE | B32: 25-62 | C32: CCH Hope Center | D32: C.G. | E32: =VLOOKUP($B32,'Foundation Inport'!$A$2:$H$67,3,FALSE) -> 104700 | F32: =IF(VLOOKUP($B32,'Foundation Inport'!$A$2:$H$592,4,FALSE)>0,VLOOKUP($B32,'Foundation Inport'!$A$2:$H$592,4,FALSE),0) -> 72825 | G32: =E32-F32 -> 31875 | H32: 15937.5 | I32: 15937.5 | R32: =G32-SUM(H32:Q32) -> 0
A33: CBUS | B33: 25-63 | C33: GISA Phase II | D33: D.S. | E33: =VLOOKUP($B33,'Foundation Inport'!$A$2:$H$67,3,FALSE) -> 434892 | F33: =IF(VLOOKUP($B33,'Foundation Inport'!$A$2:$H$592,4,FALSE)>0,VLOOKUP($B33,'Foundation Inport'!$A$2:$H$592,4,FALSE),0) -> 0 | G33: =E33-F33 -> 434892 | I33: 15000 | L33: 235892 | M33: 100000 | N33: 84000 | R33: =G33-SUM(H33:Q33) -> 0
A34: CLE | B34: 25-64 | C34: Beaver Excavating | D34: R.S. | E34: =VLOOKUP($B34,'Foundation Inport'!$A$2:$H$67,3,FALSE) -> 12300 | F34: =IF(VLOOKUP($B34,'Foundation Inport'!$A$2:$H$592,4,FALSE)>0,VLOOKUP($B34,'Foundation Inport'!$A$2:$H$592,4,FALSE),0) -> 6925.01 | G34: =E34-F34 -> 5374.99 | I34: 5374.99 | R34: =G34-SUM(H34:Q34) -> 0
A35: CBUS | B35: 25-65 | C35: FCOT Front Entry Vestibule | D35: C.G. | E35: =VLOOKUP($B35,'Foundation Inport'!$A$2:$H$67,3,FALSE) -> 178980.93 | F35: =IF(VLOOKUP($B35,'Foundation Inport'!$A$2:$H$592,4,FALSE)>0,VLOOKUP($B35,'Foundation Inport'!$A$2:$H$592,4,FALSE),0) -> 0 | G35: =E35-F35 -> 178980.93 | H35: 86154.93 | I35: 23478.5 | J35: =138695/2 -> 69347.5 | R35: =G35-SUM(H35:Q35) -> 0
A36: CBUS | B36: 25-66 | C36: 9th & High | D36: S.M. | E36: =VLOOKUP($B36,'Foundation Inport'!$A$2:$H$67,3,FALSE) -> 478940 | F36: =IF(VLOOKUP($B36,'Foundation Inport'!$A$2:$H$592,4,FALSE)>0,VLOOKUP($B36,'Foundation Inport'!$A$2:$H$592,4,FALSE),0) -> 0 | G36: =E36-F36 -> 478940 | I36: 32750 | K36: 35000 | L36: 150000 | M36: 178940 | N36: 94800 | R36: =G36-SUM(H36:Q36) -> -12550
A37: CLE | B37: 25-67 | C37: Coltene Office Refresh | D37: D.S. | E37: =VLOOKUP($B37,'Foundation Inport'!$A$2:$H$67,3,FALSE) -> 52180 | F37: =IF(VLOOKUP($B37,'Foundation Inport'!$A$2:$H$592,4,FALSE)>0,VLOOKUP($B37,'Foundation Inport'!$A$2:$H$592,4,FALSE),0) -> 0 | G37: =E37-F37 -> 52180 | K37: 48680 | L37: 3500 | R37: =G37-SUM(H37:Q37) -> 0
A38: CLE | B38: 25-68 | C38: Pure Ohio Wellness Dispensary | D38: S.M. | E38: =VLOOKUP($B38,'Foundation Inport'!$A$2:$H$67,3,FALSE) -> 16900 | F38: =IF(VLOOKUP($B38,'Foundation Inport'!$A$2:$H$592,4,FALSE)>0,VLOOKUP($B38,'Foundation Inport'!$A$2:$H$592,4,FALSE),0) -> 0 | G38: =E38-F38 -> 16900 | H38: 16900 | K38: 0 | R38: =G38-SUM(H38:Q38) -> 0
A39: CBUS | B39: 25-70 | C39: Target Mansfield | D39: R.S. | E39: =VLOOKUP($B39,'Foundation Inport'!$A$2:$H$67,3,FALSE) -> 8000 | F39: =IF(VLOOKUP($B39,'Foundation Inport'!$A$2:$H$592,4,FALSE)>0,VLOOKUP($B39,'Foundation Inport'!$A$2:$H$592,4,FALSE),0) -> 3600 | G39: =E39-F39 -> 4400 | J39: 4400 | R39: =G39-SUM(H39:Q39) -> 0
A40: CBUS | B40: 25-71 | C40: King Arts | D40: TBD | E40: =VLOOKUP($B40,'Foundation Inport'!$A$2:$H$67,3,FALSE) -> 5815 | F40: =IF(VLOOKUP($B40,'Foundation Inport'!$A$2:$H$592,4,FALSE)>0,VLOOKUP($B40,'Foundation Inport'!$A$2:$H$592,4,FALSE),0) -> 2565 | G40: =E40-F40 -> 3250 | L40: 3250 | R40: =G40-SUM(H40:Q40) -> 0
...

Sheet Projected Monthly Rev
A1: Company Wide
A3: Mar-26 | B3: Apr-26 | C3: May-26 | D3: Jun-26 | E3: Jul-26 | F3: Aug-26 | G3: Sep-26 | H3: Oct-26 | I3: Nov-26 | J3: Dec-26
A4: =SUM('Active Jobs Sheet'!H2:H77) -> 687677.13 | B4: =SUM('Active Jobs Sheet'!I2:I77) -> 955676.79 | C4: =SUM('Active Jobs Sheet'!J2:J77) -> 688177.84 | D4: =SUM('Active Jobs Sheet'!K2:K77) -> 476801.03 | E4: =SUM('Active Jobs Sheet'!L2:L77) -> 626414.19 | F4: =SUM('Active Jobs Sheet'!M2:M77) -> 390940 | G4: =SUM('Active Jobs Sheet'!N2:N77) -> 278800 | H4: =SUM('Active Jobs Sheet'!O2:O77) -> 96910 | ... J4: =SUM('Active Jobs Sheet'!Q2:Q77) -> 0

Sheet CBUS Projected Monthly Revenues
A1: COLUMBUS
A3: Mar-26 | B3: Apr-26 | C3: May-26 | D3: Jun-26 | E3: Jul-26 | F3: Aug-26 | G3: Sep-26 | H3: Oct-26 | I3: Nov-26 | J3: Dec-26
A4: =SUMIF('Active Jobs Sheet'!$A$2:$A$75,"CBUS",('Active Jobs Sheet'!H2:H77)) -> 409162.46 | B4: =SUMIF('Active Jobs Sheet'!$A$2:$A$75,"CBUS",('Active Jobs Sheet'!I2:I77)) -> 562231.64 | C4: =SUMIF('Active Jobs Sheet'!$A$2:$A$75,"CBUS",('Active Jobs Sheet'!J2:J77)) -> 407970.84 | D4: =SUMIF('Active Jobs Sheet'!$A$2:$A$75,"CBUS",('Active Jobs Sheet'!K2:K77)) -> 142737 | E4: =SUMIF('Active Jobs Sheet'!$A$2:$A$75,"CBUS",('Active Jobs Sheet'!L2:L77)) -> 540049.19 | F4: =SUMIF('Active Jobs Sheet'!$A$2:$A$75,"CBUS",('Active Jobs Sheet'!M2:M77)) -> 390940 | G4: =SUMIF('Active Jobs Sheet'!$A$2:$A$75,"CBUS",('Active Jobs Sheet'!N2:N77)) -> 278800 | H4: =SUMIF('Active Jobs Sheet'!$A$2:$A$75,"CBUS",('Active Jobs Sheet'!O2:O77)) -> 96910 | ... J4: =SUMIF('Active Jobs Sheet'!$A$2:$A$75,"CBUS",('Active Jobs Sheet'!Q2:Q77)) -> 0

Sheet CLE Projected Monthly Rev
A1: Cleveland
A3: Mar-26 | B3: Apr-26 | C3: May-26 | D3: Jun-26 | E3: Jul-26 | F3: Aug-26 | G3: Sep-26 | H3: Oct-26 | I3: Nov-26 | J3: Dec-26
A4: =SUMIF('Active Jobs Sheet'!$A$2:$A$75,"CLE",('Active Jobs Sheet'!H2:H77)) -> 278514.67 | B4: =SUMIF('Active Jobs Sheet'!$A$2:$A$75,"CLE",('Active Jobs Sheet'!I2:I77)) -> 393445.15 | C4: =SUMIF('Active Jobs Sheet'!$A$2:$A$75,"CLE",('Active Jobs Sheet'!J2:J77)) -> 280207 | D4: =SUMIF('Active Jobs Sheet'!$A$2:$A$75,"CLE",('Active Jobs Sheet'!K2:K77)) -> 334064.03 | E4: =SUMIF('Active Jobs Sheet'!$A$2:$A$75,"CLE",('Active Jobs Sheet'!L2:L77)) -> 86365 | F4: =SUMIF('Active Jobs Sheet'!$A$2:$A$75,"CLE",('Active Jobs Sheet'!M2:M77)) -> 0 | G4: =SUMIF('Active Jobs Sheet'!$A$2:$A$75,"CLE",('Active Jobs Sheet'!N2:N77)) -> 0 | H4: =SUMIF('Active Jobs Sheet'!$A$2:$A$75,"CLE",('Active Jobs Sheet'!O2:O77)) -> 0 | ... J4: =SUMIF('Active Jobs Sheet'!$A$2:$A$75,"CLE",('Active Jobs Sheet'!Q2:Q77)) -> 0

Sheet Projected Annual Income Remanin
A1: 2025 | B1: 2026 | G1: 2025 Billed to Date | H1: 2026 Billed to Date | I1: 2026 Balance to Match 2025
A2: =G2 -> 12030822 | B2: =SUM('Active Jobs Sheet'!H2:Q77)+H2 -> 5209222 | G2: 12030822 | H2: 1007825 | I2: =G2-Table2[[#This Row],[2026]] -> 6821600

Sheet Foundation Inport
A1: Job No | B1: Job Description | C1: Revised Contract | D1: Billings
A2: 23-22 | B2: GSA Celebrezze Envelope | C2: 309888.75 | D2: 266144.9
A3: 23-46 | B3: Galaxy at Polaris Bldg 1 | C3: 637845.28 | D3: 637845.28
A4: 24-03 | B4: Hap Creamean | C4: 392196.38 | D4: 392196.38
A5: 24-13 | B5: TWHS Natatorium | C5: 416108.63 | D5: 416108.63
A6: 24-22 | B6: Daimler Truck | C6: 655214.83 | D6: 499895.2
A7: 24-26 | B7: St Michael of the Arch | C7: 81936.5 | D7: 81936.5
A8: 24-34 | B8: Pickerington Central JHS | C8: 1438021.3 | D8: 1416391.3
A9: 24-45 | B9: Columbus Fire Station 36 | C9: 196562 | D9: 155550
A10: 24-50 | B10: North Olmsted PK-5 | C10: 1949570.4 | D10: 1499798.9
A11: 24-55 | B11: Amherst Transportation Bldg | C11: 75507.6 | D11: 46635.09
A12: 24-56 | B12: Lake County Executive Airport | C12: 323945.76 | D12: 262683.83
A13: 25-01 | B13: Westerville City Hall | C13: 1010713.8 | D13: 765217.42
... A63: 25-72 | B63: Francis Apartments | C63: 54375 | D63: 0
A64: 26-01 | B64: Ethos Centerpoint Church | C64: =2345+230540+77525 -> 310410 | D64: 0
A65: 26-02 | B65: Beechwood UH | C65: 100000 | D65: 0
A66: 26-03 | B66: Old Fire Station 10 Reno | C66: 99340 | D66: 0
A67: 26-04 | B67: Broad Street Apartments | C67: 89827.19 | D67: 0
A68: 26-05 | B68: KEP Door HW Replacements | C68: 5670 | D68: 0
A69: 26-06 | B69: West 26th Apartments | C69: 46400 | D69: 0
A70: 26-07 | B70: Mentor Integra | C70: 26660 | D70: 0
A71: 26-08 | B71: Pivotal Pointe Hub 27 | C71: 46465 | D71: 0
A72: 26-09 | B72: McGregor Pace Service | C72: 9340 | D72: 0
A73: 26-10 | B73: Seasons 6 Glass Replacement | C73: 4395 | D73: 0
